Workbook

Sheet REPORT
A1: using data from 4/1/25 to 3/31/26
A2: Total Gifts Special Events | B2: =COUNTIF(RAW!I:I, "Special Events") -> 1277 | D2: Total Gifts Special Events | E2: =COUNTIF(RAW!I:I, "Third Party Events") -> 593
A3: Total amount Special events | B3: =SUMIFS(RAW!C:C,RAW!I:I, "Special Events") -> 367015.58 | D3: Total amount Special events | E3: =SUMIFS(RAW!C:C,RAW!I:I, "Third Party Events") -> 323818.23
A5: Special Events Goal | B5: 190000 | D5: Third Party Goal | E5: 280000
A6: % to Goal | B6: =B3/B5 -> 1.9316609 | D6: % to Goal | E6: =E3/E5 -> 1.1564937
A8: Gift Type | B8: Amount | C8: % of gifts
A9: cash | B9: =COUNTIFS(RAW!F:F, "Cash") -> 1852 | C9: =B9/($B$2+$E$2) -> 0.99037433
A10: GiK (Securities) | B10: =COUNTIFS(RAW!F:F, "Gift-in-Kind") -> 16 | C10: =B10/($B$2+$E$2) -> 0.0085561497
A11: Other | B11: =COUNTIFS(RAW!F:F, "Other") -> 1 | C11: =B11/($B$2+$E$2) -> 0.00053475936
A12: Pledge Payment | B12: =COUNTIFS(RAW!F:F, "Pay-Cash") -> 1 | C12: =B12/($B$2+$E$2) -> 0.00053475936
A14: Gift By Fund | B14: Amount | C14: % | D14: Gift By Fund | E14: Amount | F14: %
A15: MRFD 2025 | B15: =SUMIFS(RAW!C:C, RAW!I:I, "Special Events", RAW!B:B, A15) -> 94315.7 | C15: =B15/$B$3 -> 0.2569801 | D15: Third Party Event | E15: =SUMIFS(RAW!C:C, RAW!I:I, "Third Party Events", RAW!B:B, D15) -> 75616.23 | F15: =E15/$E$3 -> 0.23351443
A16: LOH2025 | B16: =SUMIFS(RAW!C:C, RAW!I:I, "Special Events", RAW!B:B, A16) -> 84585.98 | C16: =B16/$B$3 -> 0.23046973 | D16: Cava | E16: =SUMIFS(RAW!C:C, RAW!I:I, "Third Party Events", RAW!B:B, D16) -> 46100 | F16: =E16/$E$3 -> 0.14236382
A17: Secret | B17: =SUMIFS(RAW!C:C, RAW!I:I, "Special Events", RAW!B:B, A17) -> 70802.9 | C17: =B17/$B$3 -> 0.19291524 | D17: Heart Cookies | E17: =SUMIFS(RAW!C:C, RAW!I:I, "Third Party Events", RAW!B:B, D17) -> 60423.85 | F17: =E17/$E$3 -> 0.18659805
A18: CTC 2025 | B18: =SUMIFS(RAW!C:C, RAW!I:I, "Special Events", RAW!B:B, A18) -> 56916 | C18: =B18/$B$3 -> 0.15507789 | D18: Spirit of Children | E18: =SUMIFS(RAW!C:C, RAW!I:I, "Third Party Events", RAW!B:B, D18) -> 20878 | F18: =E18/$E$3 -> 0.064474443
A19: CTC 2026 | B19: =SUMIFS(RAW!C:C, RAW!I:I, "Special Events", RAW!B:B, A19) -> 51635 | C19: =B19/$B$3 -> 0.14068885 | D19: Rita B Mem Pool | E19: =SUMIFS(RAW!C:C, RAW!I:I, "Third Party Events", RAW!B:B, D19) -> 20500 | F19: =E19/$E$3 -> 0.063307121
A20: LOH2026 | B20: =SUMIFS(RAW!C:C, RAW!I:I, "Special Events", RAW!B:B, A20) -> 5000 | C20: =B20/$B$3 -> 0.0136234 | D20: Darryl Penasi | E20: =SUMIFS(RAW!C:C, RAW!I:I, "Third Party Events", RAW!B:B, D20) -> 15715 | F20: =E20/$E$3 -> 0.048530313
A21: MRFD 2026 | B21: =SUMIFS(RAW!C:C, RAW!I:I, "Special Events", RAW!B:B, A21) -> 2300 | C21: =B21/$B$3 -> 0.0062667639 | D21: Burgers | E21: =SUMIFS(RAW!C:C, RAW!I:I, "Third Party Events", RAW!B:B, D21) -> 13524 | F21: =E21/$E$3 -> 0.041764171
A22: SAHB2019 | B22: =SUMIFS(RAW!C:C, RAW!I:I, "Special Events", RAW!B:B, A22) -> 1000 | C22: =B22/$B$3 -> 0.00272468 | D22: Spruce Creek | E22: =SUMIFS(RAW!C:C, RAW!I:I, "Third Party Events", RAW!B:B, D22) -> 13336.86 | F22: =E22/$E$3 -> 0.041186254
A23: Tree of Hope | B23: =SUMIFS(RAW!C:C, RAW!I:I, "Special Events", RAW!B:B, A23) -> 260 | C23: =B23/$B$3 -> 0.00070841679 | D23: SILVERFOX | E23: =SUMIFS(RAW!C:C, RAW!I:I, "Third Party Events", RAW!B:B, D23) -> 8694.29 | F23: =E23/$E$3 -> 0.026849291
A24: MRFD 2024 | B24: =SUMIFS(RAW!C:C, RAW!I:I, "Special Events", RAW!B:B, A24) -> 100 | C24: =B24/$B$3 -> 0.000272468 | D24: TBAC | E24: =SUMIFS(RAW!C:C, RAW!I:I, "Third Party Events", RAW!B:B, D24) -> 7342.7 | F24: =E24/$E$3 -> 0.022675376
A25: SAHB2023 | B25: =SUMIFS(RAW!C:C, RAW!I:I, "Special Events", RAW!B:B, A25) -> 100 | C25: =B25/$B$3 -> 0.000272468 | D25: 50K | E25: =SUMIFS(RAW!C:C, RAW!I:I, "Third Party Events", RAW!B:B, D25) -> 8456 | F25: =E25/$E$3 -> 0.026113416
C26: =SUM(C15:C25) -> 1 | D26: JW Lemonade | E26: =SUMIFS(RAW!C:C, RAW!I:I, "Third Party Events", RAW!B:B, D26) -> 6542.31 | F26: =E26/$E$3 -> 0.020203649
D27: Jersey Auction - LU | E27: =SUMIFS(RAW!C:C, RAW!I:I, "Third Party Events", RAW!B:B, D27) -> 6000 | F27: =E27/$E$3 -> 0.018528914
D28: JB Golf Tourn | E28: =SUMIFS(RAW!C:C, RAW!I:I, "Third Party Events", RAW!B:B, D28) -> 5375 | F28: =E28/$E$3 -> 0.016598818
D29: Fun in the Sun | E29: =SUMIFS(RAW!C:C, RAW!I:I, "Third Party Events", RAW!B:B, D29) -> 3000 | F29: =E29/$E$3 -> 0.0092644568
D30: CFC | E30: =SUMIFS(RAW!C:C, RAW!I:I, "Third Party Events", RAW!B:B, D30) -> 2937.05 | F30: =E30/$E$3 -> 0.0090700576
D31: Barbells | E31: =SUMIFS(RAW!C:C, RAW!I:I, "Third Party Events", RAW!B:B, D31) -> 2700 | F31: =E31/$E$3 -> 0.0083380111
D32: Glenice Quesnelle | E32: =SUMIFS(RAW!C:C, RAW!I:I, "Third Party Events", RAW!B:B, D32) -> 2000 | F32: =E32/$E$3 -> 0.0061763045
D33: Queens | E33: =SUMIFS(RAW!C:C, RAW!I:I, "Third Party Events", RAW!B:B, D33) -> 1783.56 | F33: =E33/$E$3 -> 0.0055079049
D34: Fallen Stripes | E34: =SUMIFS(RAW!C:C, RAW!I:I, "Third Party Events", RAW!B:B, D34) -> 1200 | F34: =E34/$E$3 -> 0.0037057827
D35: Dancing Docs | E35: =SUMIFS(RAW!C:C, RAW!I:I, "Third Party Events", RAW!B:B, D35) -> 1000 | F35: =E35/$E$3 -> 0.0030881523
D36: Share a Heart | E36: =SUMIFS(RAW!C:C, RAW!I:I, "Third Party Events", RAW!B:B, D36) -> 282 | F36: =E36/$E$3 -> 0.00087085894
D37: MISC | E37: =SUMIFS(RAW!C:C, RAW!I:I, "Third Party Events", RAW!B:B, D37) -> 241.38 | F37: =E37/$E$3 -> 0.00074541819
D38: ThinkPink2025 | E38: =SUMIFS(RAW!C:C, RAW!I:I, "Third Party Events", RAW!B:B, D38) -> 170 | F38: =E38/$E$3 -> 0.00052498588
F39: =SUM(F15:F38) -> 1

Sheet RAW
A1: Primary Addressee | B1: Appeal ID | C1: Appeal Split Amount | D1: Fund Description | E1: Gift ID | F1: Gift Type | G1: Gift Reference | H1: Gift Date | I1: Appeal Category
A2: Mrs. Diane Hunter | B2: 50K | C2: 100 | D2: Breast Cancer Fund | E2: 548126 | F2: Cash | H2: 46056 | I2: Third Party Events
A3: Mr. Jarrid Sawicki | B3: 50K | C3: 50 | D3: Breast Cancer Fund | E3: 548137 | F3: Cash | H3: 46056 | I3: Third Party Events
A4: Mrs. Kelly Tait | B4: 50K | C4: 25 | D4: Breast Cancer Fund | E4: 548138 | F4: Cash | H4: 46056 | I4: Third Party Events
A5: Mrs. Mackenzie Nelson | B5: 50K | C5: 25 | D5: Breast Cancer Fund | E5: 548139 | F5: Cash | H5: 46056 | I5: Third Party Events
A6: Lindsay & Lenore Doran-Bonk | B6: 50K | C6: 50 | D6: Breast Cancer Fund | E6: 548140 | F6: Cash | H6: 46056 | I6: Third Party Events
A7: Mrs. Amanda Ross | B7: 50K | C7: 25 | D7: Breast Cancer Fund | E7: 548141 | F7: Cash | H7: 46056 | I7: Third Party Events
A8: Mrs. Andrea Javellana | B8: 50K | C8: 25 | D8: Breast Cancer Fund | E8: 548176 | F8: Cash | H8: 46059 | I8: Third Party Events
A9: Mr. Sean Arruda | B9: 50K | C9: 75 | D9: Breast Cancer Fund | E9: 548298 | F9: Cash | H9: 46064 | I9: Third Party Events
A10: Mrs. Sarah Boyechko | B10: 50K | C10: 50 | D10: Breast Cancer Fund | E10: 548299 | F10: Cash | H10: 46064 | I10: Third Party Events
A11: Mr. Gregory Hearn | B11: 50K | C11: 50 | D11: Breast Cancer Fund | E11: 548300 | F11: Cash | H11: 46064 | I11: Third Party Events
A12: Ms. Sharon J. Sidlar | B12: 50K | C12: 50 | D12: Breast Cancer Fund | E12: 548306 | F12: Cash | H12: 46065 | I12: Third Party Events
A13: Mr. Steven Anderson | B13: 50K | C13: 50 | D13: Breast Cancer Fund | E13: 548307 | F13: Cash | H13: 46065 | I13: Third Party Events
... A16: Mr. Wayne & Mrs. Kelly Maunula | B16: 50K | C16: 5000 | D16: Breast Cancer Fund | E16: 548434 | F16: Cash | H16: 46073 | I16: Third Party Events
A17: Mrs. Sandi Hunter | B17: 50K | C17: 25 | D17: Northern Cancer Fund | E17: 548908 | F17: Cash | G17: 50 for 50 Loppet challenge Colin Hunter | H17: 46075 | I17: Third Party Events
A18: Mrs. Susan Rochon | B18: 50K | C18: 50 | D18: Breast Cancer Fund | E18: 549145 | F18: Cash | H18: 46078 | I18: Third Party Events
A19: Pat Auffret | B19: 50K | C19: 50 | D19: Breast Cancer Fund | E19: 549146 | F19: Cash | H19: 46078 | I19: Third Party Events
A20: Mrs. Victoria Holland | B20: 50K | C20: 25 | D20: Breast Cancer Fund | E20: 549151 | F20: Cash | H20: 46078 | I20: Third Party Events
A21: Ms. Rheana Gomez | B21: 50K | C21: 25 | D21: Breast Cancer Fund | E21: 549152 | F21: Cash | H21: 46078 | I21: Third Party Events
A22: Jody Corbett | B22: 50K | C22: 25 | D22: Breast Cancer Fund | E22: 549148 | F22: Cash | H22: 46078 | I22: Third Party Events
A23: Keith W Ailey | B23: 50K | C23: 25 | D23: Breast Cancer Fund | E23: 549174 | F23: Cash | H23: 46080 | I23: Third Party Events
A24: Mrs. Danielle Brown | B24: 50K | C24: 50 | D24: Breast Cancer Fund | E24: 549175 | F24: Cash | H24: 46080 | I24: Third Party Events
A25: Mr. Andrei Rosario | B25: 50K | C25: 5 | D25: Breast Cancer Fund | E25: 549176 | F25: Cash | H25: 46080 | I25: Third Party Events
A26: Glenn and Laura Craig | B26: 50K | C26: 100 | D26: Breast Cancer Fund | E26: 549177 | F26: Cash | H26: 46080 | I26: Third Party Events
A27: Dr. Abdelhamid Tayebi | B27: 50K | C27: 100 | D27: Breast Cancer Fund | E27: 549307 | F27: Cash | H27: 46086 | I27: Third Party Events
A28: Mrs. Susan J. Childs | B28: 50K | C28: 100 | D28: Breast Cancer Fund | E28: 549308 | F28: Cash | H28: 46086 | I28: Third Party Events
A29: Mr. Thomas Collins | B29: 50K | C29: 10 | D29: Breast Cancer Fund | E29: 549309 | F29: Cash | H29: 46086 | I29: Third Party Events
... A34: Mr. Todd Randall & Ms. Mira Majerovich | B34: 50K | C34: 50 | D34: Breast Cancer Fund | E34: 549314 | F34: Cash | H34: 46090 | I34: Third Party Events
A35: Mr. Michael Noonan | B35: 50K | C35: 20 | D35: Breast Cancer Fund | E35: 549287 | F35: Cash | G35: Colin Hunter | H35: 46090 | I35: Third Party Events
A36: Mark Craig | B36: 50K | C36: 200 | D36: Breast Cancer Fund | E36: 549288 | F36: Cash | G36: Colin Hunter | H36: 46090 | I36: Third Party Events
A37: Ms. Kira Barkley | B37: 50K | C37: 10 | D37: Breast Cancer Fund | E37: 549289 | F37: Cash | G37: Colin Hunter | H37: 46090 | I37: Third Party Events
A38: Ms. Sara Alves | B38: 50K | C38: 10 | D38: Breast Cancer Fund | E38: 549290 | F38: Cash | G38: Colin Hunter | H38: 46090 | I38: Third Party Events
A39: Anonymous Donations | B39: 50K | C39: 155 | D39: Breast Cancer Fund | E39: 549291 | F39: Cash | G39: Colin Hunter | H39: 46090 | I39: Third Party Events
A40: Ms. Nicole Deschamps | B40: 50K | C40: 25 | D40: Breast Cancer Fund | E40: 549386 | F40: Cash | H40: 46091 | I40: Third Party Events
A41: Ms. Ann Marie Caruk | B41: 50K | C41: 100 | D41: Breast Cancer Fund | E41: 549387 | F41: Cash | H41: 46091 | I41: Third Party Events
A42: Mrs. Lori Vander Ploeg | B42: 50K | C42: 100 | D42: Breast Cancer Fund | E42: 549388 | F42: Cash | H42: 46091 | I42: Third Party Events
A43: Wendy Niccolli | B43: 50K | C43: 25 | D43: Breast Cancer Fund | E43: 549389 | F43: Cash | H43: 46091 | I43: Third Party Events
A44: Mr. and Ms. Gabriel Tarini | B44: 50K | C44: 50 | D44: Breast Cancer Fund | E44: 549390 | F44: Cash | H44: 46091 | I44: Third Party Events
A45: Mr. John Remus-Everitt | B45: 50K | C45: 100 | D45: Breast Cancer Fund | E45: 549391 | F45: Cash | H45: 46091 | I45: Third Party Events
A46: Mrs. Anne Werbowetski | B46: 50K | C46: 100 | D46: Breast Cancer Fund | E46: 549392 | F46: Cash | H46: 46091 | I46: Third Party Events
...

Sheet INSTRUCTIONS
A1: IMPORTANT: PLEASE MAKE A COPY OF THIS FILE BEFORE WORKING ON IT
A3: 1. Export Data from RE Query: Reporting > Legacy report query raw data
A5: 2. Delete all information in the RAW tab
A7: 3. Copy the exported information to the RAW tab
A9: 4. Update the red cells
A10: data marked in red has to be updated manually, can't be exported from RE :( | G10: Data marked in blue is updated automatically based on info in RAW
